<?xml version="1.0"?>
<!--
  Copyright (C) 2019-2023 Rhys Mainwaring

  This program is free software: you can redistribute it and/or modify
  it under the terms of the GNU General Public License as published by
  the Free Software Foundation, either version 3 of the License, or
  (at your option) any later version.

  This program is distributed in the hope that it will be useful,
  but WITHOUT ANY WARRANTY; without even the implied warranty of
  MERCHANTABILITY or FITNESS FOR A PARTICULAR PURPOSE.  See the
  GNU General Public License for more details.

  You should have received a copy of the GNU General Public License
  along with this program.  If not, see <https://www.gnu.org/licenses/>.
-->
<sdf version="1.6">
  <model name="land_yacht">

    <!-- Base -->
    <link name="base_link">
      <!-- Main beam -->
      <visual name="base">
        <geometry>
          <mesh>
            <uri>model://land_yacht/meshes/land_yacht_base.stl</uri>
          </mesh>
        </geometry>
        <material>
          <ambient>0.5 0.5 0.5 1.0</ambient>
          <diffuse>0.5 0.5 0.5 1.0</diffuse>
          <specular>0.1 0.1 0.1 1.0</specular>
        </material>
      </visual>

      <visual name="steering_visual">
        <pose>0.89 0 0 0 0 0</pose>
        <geometry>
          <mesh>
            <uri>model://land_yacht/meshes/steering_assembly_v3.stl</uri>
          </mesh>
        </geometry>
        <material>
          <ambient>0.5 0.5 0.5 1.0</ambient>
          <diffuse>0.5 0.5 0.5 1.0</diffuse>
          <specular>0.1 0.1 0.1 1.0</specular>
        </material>
      </visual>

      <visual name="motor_visual">
        <pose>0.57 0 0.22 0 0 0</pose>
        <geometry>
          <mesh>
            <uri>model://land_yacht/meshes/motor_mount_v2.stl</uri>
          </mesh>
        </geometry>
        <material>
          <ambient>0.5 0.5 0.5 1.0</ambient>
          <diffuse>0.5 0.5 0.5 1.0</diffuse>
          <specular>0.1 0.1 0.1 1.0</specular>
        </material>
      </visual>

      <!-- Main beam -->
      <collision name="main_beam_collision">
        <pose>0.4 0 0.025 0 0 0</pose>
        <geometry>
          <box>
            <size>1.0 0.020 0.020</size>
          </box>
        </geometry>
      </collision>

      <!-- Cross beam -->
      <collision name="cross_beam_collision">
        <pose>0 0 0 0 0 0</pose>
        <geometry>
          <box>
            <size>0.020 1.0 0.020</size>
          </box>
        </geometry>
      </collision>

      <visual name="imu_visual">
        <pose>0.05 0 0.06 0 0 0</pose>
        <geometry>
          <box>
            <size>0.06 0.04 0.01</size>
          </box>
        </geometry>
        <material>
          <ambient>0.0 1.0 0.0 1.0</ambient>
          <diffuse>0.0 1.0 0.0 1.0</diffuse>
          <specular>0.1 0.1 0.1 1.0</specular>
        </material>
      </visual>

      <sensor name="imu_sensor" type="imu">
        <pose>0.05 0 0.06 3.141593 0 0</pose>
        <always_on>1</always_on>
        <update_rate>1000</update_rate>
        <visualize>1</visualize>
      </sensor>

      <!-- <sensor name="camera" type="camera">
        <always_on>1</always_on>
        <update_rate>30</update_rate>
        <camera name="camera">
          <horizontal_fov>1.047</horizontal_fov>
          <image>
            <width>800</width>
            <height>800</height>
            <format>R8G8B8</format>
          </image>
          <clip>
            <near>0.02</near>
            <far>300</far>
          </clip>
        </camera>
        <pose>0.5 0 0.3 0 0 0</pose>
      </sensor> -->

      <!-- <sensor name="anemometer_sensor" type="anemometer">
        <pose>0 0 0 0 0 0</pose>
        <always_on>true</always_on>
        <update_rate>50</update_rate>
        <topic>anemometer</topic>
      </sensor>

      <visual name="anemometer_visual">
        <pose>0 0 0 0 0 0</pose>
        <geometry>
          <cylinder>
            <radius>0.025</radius>
            <length>0.025</length>
          </cylinder>
        </geometry>
        <material>
          <ambient>1.0 0.0 0.0 1.0</ambient>
          <diffuse>1.0 0.0 0.0 1.0</diffuse>
          <specular>0.1 0.1 0.1 1.0</specular>
        </material>
      </visual> -->

      <!-- Approximate LY base inertial with a solid cuboid:
        m  = 3.544 kg
        Lx = 0.25 m
        Ly = 0.16 m
        Lz = 0.06 m

        as most of the mass is located at the 
        intersection of the two beams.
      -->
      <inertial>
        <pose>0.15 0 0.04 0 0 0</pose>
        <mass>3.544</mass>
        <inertia>
          <ixx>0.008623733</ixx>
          <ixy>0</ixy>
          <iyy>0.019521533</iyy>
          <iyz>0</iyz>
          <izz>0.026018867</izz>
        </inertia>
      </inertial>
    </link>

    <!-- Right wheel -->
    <link name="right_wheel_link">
      <pose>0 -0.512 0 1.570796327 0 0</pose>
      <visual name="right_wheel_visual">
        <geometry>
          <mesh>
            <uri>model://land_yacht/meshes/sand_wheel.stl</uri>
          </mesh>
        </geometry>
        <material>
          <ambient>0.5 0.5 0.5 1.0</ambient>
          <diffuse>0.5 0.5 0.5 1.0</diffuse>
          <specular>0.1 0.1 0.1 1.0</specular>
        </material>
      </visual>
      <collision name="right_wheel_collision">
        <geometry>
          <cylinder>
            <radius>0.0750</radius>
            <length>0.0235</length>
          </cylinder>
        </geometry>
      </collision>
      <inertial>
        <mass>0.112</mass>
        <inertia>
          <ixx>0.000162654</ixx>
          <ixy>0</ixy>
          <iyy>0.000162654</iyy>
          <iyz>0</iyz>
          <izz>0.000315</izz>
        </inertia>
      </inertial>
    </link>

    <joint type="revolute" name="right_wheel_joint">
      <pose>0 0 0 0 0 0</pose>
      <child>right_wheel_link</child>
      <parent>base_link</parent>
      <axis>
        <xyz>0 0 1</xyz>
        <dynamics>
          <damping>0.001</damping>
        </dynamics>
      </axis>
    </joint>

    <!-- Left wheel -->
    <link name="left_wheel_link">
      <pose>0 0.512 0 1.570796327 0 0</pose>
      <visual name="left_wheel_visual">
        <geometry>
          <mesh>
            <uri>model://land_yacht/meshes/sand_wheel.stl</uri>
          </mesh>
        </geometry>
        <material>
          <ambient>0.5 0.5 0.5 1.0</ambient>
          <diffuse>0.5 0.5 0.5 1.0</diffuse>
          <specular>0.1 0.1 0.1 1.0</specular>
        </material>
      </visual>
      <collision name="left_wheel_collision">
        <geometry>
          <cylinder>
            <radius>0.0750</radius>
            <length>0.0235</length>
          </cylinder>
        </geometry>
      </collision>
      <inertial>
        <mass>0.112</mass>
        <inertia>
          <ixx>0.000162654</ixx>
          <ixy>0</ixy>
          <iyy>0.000162654</iyy>
          <iyz>0</iyz>
          <izz>0.000315</izz>
        </inertia>
      </inertial>
    </link>

    <joint type="revolute" name="left_wheel_joint">
      <pose>0 0 0 0 0 0</pose>
      <child>left_wheel_link</child>
      <parent>base_link</parent>
      <axis>
        <xyz>0 0 1</xyz>
        <dynamics>
          <damping>0.001</damping>
        </dynamics>
      </axis>
    </joint>

    <!-- Steering unit -->
    <link name="steering_link">
      <pose>1.05 0 0 0 0 0</pose>

      <visual name="steering_visual">
        <pose>0 0 0 0 0 0</pose>
        <geometry>
          <mesh>
            <uri>model://land_yacht/meshes/land_yacht_forks_v4.stl</uri>
          </mesh>
        </geometry>
        <material>
          <ambient>0.5 0.5 0.5 1.0</ambient>
          <diffuse>0.5 0.5 0.5 1.0</diffuse>
          <specular>0.1 0.1 0.1 1.0</specular>
        </material>
      </visual>
      <collision name="steering_collision">
        <pose>-0.05 0 0.01 0 0 0</pose>
        <geometry>
          <box>
            <size>0.14 0.05 0.05</size>
          </box>
        </geometry>
      </collision>

      <inertial>
        <pose>-0.05 0 0.01 0 0 0</pose>
        <mass>0.073</mass>
        <inertia>
          <ixx>3.04167E-05</ixx>
          <ixy>0</ixy>
          <iyy>0.000134442</iyy>
          <iyz>0</iyz>
          <izz>0.000134442</izz>
        </inertia>
      </inertial>
    </link>

    <joint type="revolute" name="steering_joint">
      <pose>-0.114 0 0.045 0 0 0</pose>
      <child>steering_link</child>
      <parent>base_link</parent>
      <axis>
        <xyz>-1 0 0.700207538</xyz>
        <limit>
          <lower>-0.8</lower>
          <upper>0.8</upper>
        </limit>
      </axis>
    </joint>

    <!-- Front wheel -->
    <link name="front_wheel_link">
      <pose>1.05 0 0 1.570796327 0 0</pose>
      <visual name="front_wheel_visual">
        <geometry>
          <mesh>
            <uri>model://land_yacht/meshes/sand_wheel.stl</uri>
          </mesh>
        </geometry>
        <material>
          <ambient>0.5 0.5 0.5 1.0</ambient>
          <diffuse>0.5 0.5 0.5 1.0</diffuse>
          <specular>0.1 0.1 0.1 1.0</specular>
        </material>
      </visual>
      <collision name="front_wheel_collision">
        <geometry>
          <cylinder>
            <radius>0.0750</radius>
            <length>0.0235</length>
          </cylinder>
        </geometry>
      </collision>
      <inertial>
        <mass>0.112</mass>
        <inertia>
          <ixx>0.000162654</ixx>
          <ixy>0</ixy>
          <iyy>0.000162654</iyy>
          <iyz>0</iyz>
          <izz>0.000315</izz>
        </inertia>
      </inertial>
    </link>

    <joint type="revolute" name="front_wheel_joint">
      <pose>0 0 0 0 0 0</pose>
      <child>front_wheel_link</child>
      <parent>steering_link</parent>
      <axis>
        <xyz>0 0 1</xyz>
        <dynamics>
          <damping>0.001</damping>
        </dynamics>
      </axis>
    </joint>

    <!-- Wing sail -->
    <include>
      <pose>0.5 0 0.1 0 0 0</pose>
      <uri>model://wing_sail_with_elevator</uri>
      <name>wing_sail</name>
    </include>

    <joint type="revolute" name="wing_sail_joint">
      <child>wing_sail::wing_sail_link</child>
      <parent>base_link</parent>
      <axis>
        <xyz>0 0 1</xyz>
        <dynamics>
          <damping>0.1</damping>
        </dynamics>
      </axis>
      <sensor name="force_torque_sensor" type="force_torque">
        <always_on>true</always_on>
        <update_rate>30</update_rate>
        <visualize>true</visualize>
      </sensor>
    </joint>

    <!-- Main sail -->
    <!-- <include>
      <pose>0.5 0 0.04 0 -0.20943951 0</pose>
      <uri>model://land_yacht_main_sail</uri>
      <name>main_sail</name>
    </include>

    <joint type="revolute" name="main_sail_joint">
      <child>main_sail::main_sail_link</child>
      <parent>base_link</parent>
      <axis>
        <xyz>0 0 1</xyz>
        <dynamics>
          <damping>0.1</damping>
        </dynamics>
        <limit>
          <lower>-1.396263402</lower>
          <upper>1.396263402</upper>
        </limit>
      </axis>
      <sensor name="force_torque_sensor" type="force_torque">
        <always_on>true</always_on>
        <update_rate>30</update_rate>
        <visualize>false</visualize>
      </sensor>
    </joint> -->

    <!-- Thruster -->
    <!-- <link name="thruster_link">
      <pose>0.565 0 0.22 0 -1.570796 0</pose>
      <visual name="motor_visual">
        <geometry>
          <mesh>
            <uri>model://land_yacht/meshes/motor_t3543-05.stl</uri>
          </mesh>
        </geometry>
        <material>
          <ambient>0.5 0.5 0.5 1.0</ambient>
          <diffuse>0.5 0.5 0.5 1.0</diffuse>
          <specular>0.1 0.1 0.1 1.0</specular>
        </material>
      </visual>
      <visual name="propeller_visual">
        <pose>0 0 0.05 3.141592654 0 0</pose>
        <geometry>
          <mesh>
            <uri>model://land_yacht/meshes/propeller_9x4.7.stl</uri>
          </mesh>
        </geometry>
        <material>
          <ambient>0.5 0.5 0.5 1.0</ambient>
          <diffuse>0.5 0.5 0.5 1.0</diffuse>
          <specular>0.1 0.1 0.1 1.0</specular>
        </material>
      </visual>
      <visual name="cp_prop_blade_1_visual">
        <pose>0.084 0 0.041 0 0 0</pose>
        <geometry>
          <sphere>
            <radius>0.01</radius>
          </sphere>
        </geometry>
        <material>
          <ambient>1.0 0.0 0.0 1.0</ambient>
          <diffuse>1.0 0.0 0.0 1.0</diffuse>
          <specular>0.1 0.1 0.1 1.0</specular>
        </material>
      </visual>
      <visual name="cp_prop_blade_2_visual">
        <pose>-0.084 0 0.041 0 0 0</pose>
        <geometry>
          <sphere>
            <radius>0.01</radius>
          </sphere>
        </geometry>
        <material>
          <ambient>1.0 0.0 0.0 1.0</ambient>
          <diffuse>1.0 0.0 0.0 1.0</diffuse>
          <specular>0.1 0.1 0.1 1.0</specular>
        </material>
      </visual>
      <collision name="thruster_collision">
        <pose>0 0 0.0205 0 0 0</pose>
        <geometry>
          <cylinder>
            <radius>0.0175</radius>
            <length>0.041</length>
          </cylinder>
        </geometry>
      </collision>
      <inertial>
        <pose>0 0 0.0205 0 0 0</pose>
        <mass>0.129</mass>
        <inertia>
          <ixx>2.79473E-05</ixx>
          <ixy>0</ixy>
          <iyy>2.79473E-05</iyy>
          <iyz>0</iyz>
          <izz>1.97531E-05</izz>
        </inertia>
      </inertial>
    </link>

    <joint type="revolute" name="thruster_joint">
      <child>thruster_link</child>
      <parent>base_link</parent>
      <axis>
        <xyz>0 0 1</xyz>
        <dynamics>
          <damping>0.001</damping>
        </dynamics>
      </axis>
      <sensor name="force_torque_sensor" type="force_torque">
        <always_on>true</always_on>
        <update_rate>30</update_rate>
        <visualize>false</visualize>
      </sensor>
    </joint>

    <plugin filename="gz-sim-lift-drag-system"
        name="gz::sim::systems::LiftDrag">
      <a0>0.3</a0>
      <alpha_stall>1.4</alpha_stall>
      <cla>4.2500</cla>
      <cda>0.10</cda>
      <cma>0.00</cma>
      <cla_stall>-0.025</cla_stall>
      <cda_stall>0.0</cda_stall>
      <cma_stall>0.0</cma_stall>
      <area>0.002</area>
      <air_density>1.2041</air_density>
      <cp>0.084 0 0</cp>
      <forward>0 1 0</forward>
      <upward>0 0 1</upward>
      <link_name>thruster_link</link_name>
    </plugin>

    <plugin filename="gz-sim-lift-drag-system"
        name="gz::sim::systems::LiftDrag">
      <a0>0.3</a0>
      <alpha_stall>1.4</alpha_stall>
      <cla>4.2500</cla>
      <cda>0.10</cda>
      <cma>0.00</cma>
      <cla_stall>-0.025</cla_stall>
      <cda_stall>0.0</cda_stall>
      <cma_stall>0.0</cma_stall>
      <area>0.002</area>
      <air_density>1.2041</air_density>
      <cp>-0.084 0 0</cp>
      <forward>0 -1 0</forward>
      <upward>0 0 1</upward>
      <link_name>thruster_link</link_name>
    </plugin> -->

  </model>
</sdf>
