<?xml version="1.0"?>
<!--
  Copyright (C) 2019-2023 Rhys Mainwaring

  This program is free software: you can redistribute it and/or modify
  it under the terms of the GNU General Public License as published by
  the Free Software Foundation, either version 3 of the License, or
  (at your option) any later version.

  This program is distributed in the hope that it will be useful,
  but WITHOUT ANY WARRANTY; without even the implied warranty of
  MERCHANTABILITY or FITNESS FOR A PARTICULAR PURPOSE.  See the
  GNU General Public License for more details.

  You should have received a copy of the GNU General Public License
  along with this program.  If not, see <https://www.gnu.org/licenses/>.
-->
<sdf version="1.6">
  <model name="land_yacht">
    <pose>0 0 0.075 0 0 0</pose>
    <static>false</static>

    <!-- <plugin name="main_sail_liftdrag" filename="libSailPlugin.so">
        <a0>0.0</a0>
        <cla>6.2832</cla>
        <alpha_stall>0.1592</alpha_stall>
        <cla_stall>-0.7083</cla_stall>
        <cda>0.63662</cda>
        <area>0.4858</area>
        <fluid_density>1.2</fluid_density>
        <forward>1 0 0</forward>
        <upward>0 1 0</upward>
        <cp>-0.15 0.0 0.75</cp>
        <link_name>main_sail_link</link_name>
        <radial_symmetry>true</radial_symmetry>
        <topic>lift_drag</topic>
    </plugin> -->

    <!--  Using values from iris_with_standoffs_demo -->
    <!-- <plugin name="prop_blade_1_liftdrag" filename="libLiftDragPlugin.so">
        <a0>0.3</a0>
        <alpha_stall>1.4</alpha_stall>
        <cla>4.2500</cla>
        <cda>0.10</cda>
        <cma>0.00</cma>
        <cla_stall>-0.025</cla_stall>
        <cda_stall>0.0</cda_stall>
        <cma_stall>0.0</cma_stall>
        <area>0.002</area>
        <air_density>1.2041</air_density>
        <cp>0.084 0 0</cp>
        <forward>0 1 0</forward>
        <upward>0 0 1</upward>
        <link_name>thruster_link</link_name>
    </plugin>
    <plugin name="prop_blade_2_liftdrag" filename="libLiftDragPlugin.so">
        <a0>0.3</a0>
        <alpha_stall>1.4</alpha_stall>
        <cla>4.2500</cla>
        <cda>0.10</cda>
        <cma>0.00</cma>
        <cla_stall>-0.025</cla_stall>
        <cda_stall>0.0</cda_stall>
        <cma_stall>0.0</cma_stall>
        <area>0.002</area>
        <air_density>1.2041</air_density>
        <cp>-0.084 0 0</cp>
        <forward>0 -1 0</forward>
        <upward>0 0 1</upward>
        <link_name>thruster_link</link_name>
    </plugin> -->

    <!-- Linear approximations to lift / drag coefficient curves for NACA 0018 airfoil
        Foil stalls at approx. 14 degrees (lower in the linear approx.)
    
    -->
    <!-- <plugin name="wing_sail_liftdrag" filename="libSailPlugin.so">
        <a0>0.0</a0>
        <cla>6.2832</cla>
        <alpha_stall>0.1592</alpha_stall>
        <cla_stall>-0.7083</cla_stall>
        <cda>0.63662</cda>
        <area>0.4858</area>
        <fluid_density>1.2</fluid_density>
        <forward>1 0 0</forward>
        <upward>0 1 0</upward>
        <cp>-0.05 0.0 0.65</cp>
        <link_name>wing_sail_link</link_name>
        <radial_symmetry>true</radial_symmetry>
        <topic>lift_drag</topic>
    </plugin> -->

    <!-- <plugin name="wing_sail_elevator_liftdrag" filename="libSailPlugin.so">
        <a0>0.0</a0>
        <cla>6.2832</cla>
        <alpha_stall>0.1592</alpha_stall>
        <cla_stall>-0.7083</cla_stall>
        <cda>0.63662</cda>
        <area>0.04858</area>
        <fluid_density>1.2</fluid_density>
        <forward>1 0 0</forward>
        <upward>0 1 0</upward>
        <cp>-0.015 0.0 0.2</cp>
        <link_name>wing_sail_elevator_link</link_name>
        <radial_symmetry>true</radial_symmetry>
        <topic>lift_drag</topic>
    </plugin> -->

    <!-- <plugin name="ardupilot_plugin" filename="libArduPilotPlugin.so"> -->
    <!-- MAVLink / port settings -->
    <!-- <fdm_addr>127.0.0.1</fdm_addr>
        <fdm_port_in>9002</fdm_port_in>
        <fdm_port_out>9003</fdm_port_out>
        <connectionTimeoutMaxCount>5</connectionTimeoutMaxCount> -->

    <!-- Coordinate frames required for APM

            change model and gazebo from XYZ to XY-Z coordinates
        
            Math constants:
            PI   = 3.141592
            PI_2 = 1.570796
            PI_4 = 0.785398
        -->
    <!-- <modelXYZToAirplaneXForwardZDown>0 0 0 3.141593 0 0</modelXYZToAirplaneXForwardZDown>
        <gazeboXYZToNED>0 0 0 3.141593 0 0</gazeboXYZToNED> -->

    <!-- Sensors -->
    <!-- <imuName>base_link::imu_sensor</imuName> -->

    <!-- Control / channels -->

    <!-- SERVO1_FUNCTION 26 (GroundSteering)
            SERVO1_MIN 1000
            SERVO1_MAX 2000

            input command in [0, 1]
            
            target steering wheel (rudder) position in [-PI/4, PI/4]
            note the sign on the multiplier is negative (wheel must turn
            in the opposite direction to a rudder)
        -->
    <!-- <control channel="0">
            <jointName>steering_joint</jointName>
            <useForce>1</useForce>
            <multiplier>-1.570796</multiplier>
            <offset>-0.5</offset>
            <type>POSITION</type>
            <p_gain>20</p_gain>
            <i_gain>0.5</i_gain>
            <d_gain>0</d_gain>
            <i_max>100</i_max>
            <i_min>-100</i_min>
            <cmd_max>1000</cmd_max>
            <cmd_min>-1000</cmd_min>
        </control> -->

    <!-- SERVO3_FUNCTION 70 (Throttle)
            SERVO3_MIN 1000
            SERVO3_MAX 2000

            input command in [0, 1]
            multiplier = 800 (sets max rpm)
        -->
    <!-- <control channel="2">
            <jointName>thruster_joint</jointName>
            <useForce>1</useForce>
            <multiplier>-800</multiplier>
            <offset>0</offset>
            <type>VELOCITY</type>
            <p_gain>0.20</p_gain>
            <i_gain>0</i_gain>
            <d_gain>0</d_gain>
            <i_max>1</i_max>
            <i_min>-1</i_min>
            <cmd_max>2.5</cmd_max>
            <cmd_min>-2.5</cmd_min>
        </control> -->

    <!-- SERVO4_FUNCTION 89 (MainSail)
            SERVO4_MIN 1000
            SERVO4_MAX 2000

            input command in [0, 1]
            desired sail angle in [5, 50] deg
        -->
    <!-- <control channel="3">
            <jointName>main_sail_joint</jointName>
            <useForce>1</useForce>
            <multiplier>1.39626</multiplier>
            <offset>0</offset>
            <type>POSITION_LIMIT</type>
            <p_gain>40</p_gain>
            <i_gain>0.1</i_gain>
            <d_gain>0</d_gain>
            <i_max>100</i_max>
            <i_min>-100</i_min>
            <cmd_max>1000</cmd_max>
            <cmd_min>-1000</cmd_min>
        </control> -->


    <!-- SERVO4_FUNCTION 128 (WingSailElevator)
            SERVO4_MIN 1000
            SERVO4_MAX 2000
            SERVO4_TRIM 1000

            SAIL_ANGLE_MIN 0
            SAIL_ANGLE_MAX 10

            DEFLECTION_MAX_DEG 10

            input command in [0, 1]
            offset = -0.5
            multiplier radians(2 * DEFLECTION_MAX_DEG) = 0.34906585
            desired wingsail elevator in [-10, 10] deg
        -->
    <!-- <control channel="3">
            <jointName>wing_sail_elevator_joint</jointName>
            <useForce>1</useForce>
            <multiplier>0.34906585</multiplier>
            <offset>-0.5</offset>
            <type>POSITION</type>
            <p_gain>20</p_gain>
            <i_gain>0.1</i_gain>
            <d_gain>0</d_gain>
            <i_max>100</i_max>
            <i_min>-100</i_min>
            <cmd_max>1000</cmd_max>
            <cmd_min>-1000</cmd_min>
        </control>

    </plugin> -->

    <!-- Base -->
    <link name="base_link">
      <!-- Main beam -->
      <visual name="base">
        <geometry>
          <mesh>
            <uri>model://land_yacht/meshes/land_yacht_base.stl</uri>
          </mesh>
        </geometry>
        <material>
          <ambient>0.5 0.5 0.5 1.0</ambient>
          <diffuse>0.5 0.5 0.5 1.0</diffuse>
          <specular>0.1 0.1 0.1 1.0</specular>
        </material>
      </visual>

      <visual name="steering_visual">
        <pose>0.89 0 0 0 0 0</pose>
        <geometry>
          <mesh>
            <uri>model://land_yacht/meshes/steering_assembly_v3.stl</uri>
          </mesh>
        </geometry>
        <material>
          <ambient>0.5 0.5 0.5 1.0</ambient>
          <diffuse>0.5 0.5 0.5 1.0</diffuse>
          <specular>0.1 0.1 0.1 1.0</specular>
        </material>
      </visual>

      <visual name="motor_visual">
        <pose>0.57 0 0.22 0 0 0</pose>
        <geometry>
          <mesh>
            <uri>model://land_yacht/meshes/motor_mount_v2.stl</uri>
          </mesh>
        </geometry>
        <material>
          <ambient>0.5 0.5 0.5 1.0</ambient>
          <diffuse>0.5 0.5 0.5 1.0</diffuse>
          <specular>0.1 0.1 0.1 1.0</specular>
        </material>
      </visual>

      <!-- Main beam -->
      <collision name="main_beam_collision">
        <pose>0.4 0 0.025 0 0 0</pose>
        <geometry>
          <box>
            <size>1.0 0.020 0.020</size>
          </box>
        </geometry>
      </collision>

      <!-- Cross beam -->
      <collision name="cross_beam_collision">
        <pose>0 0 0 0 0 0</pose>
        <geometry>
          <box>
            <size>0.020 1.0 0.020</size>
          </box>
        </geometry>
      </collision>

      <visual name="imu_visual">
        <pose>0.05 0 0.06 0 0 0</pose>
        <geometry>
          <box>
            <size>0.06 0.04 0.01</size>
          </box>
        </geometry>
        <material>
          <ambient>0.0 1.0 0.0 1.0</ambient>
          <diffuse>0.0 1.0 0.0 1.0</diffuse>
          <specular>0.1 0.1 0.1 1.0</specular>
        </material>
      </visual>

      <!-- <sensor name="camera" type="camera">
        <always_on>1</always_on>
        <update_rate>30</update_rate>
        <camera name="camera">
          <horizontal_fov>1.047</horizontal_fov>
          <image>
            <width>800</width>
            <height>800</height>
            <format>R8G8B8</format>
          </image>
          <clip>
            <near>0.02</near>
            <far>300</far>
          </clip>
        </camera> -->
      <!-- <plugin name="camera_plugin" filename="libgazebo_ros_camera.so">
          <alwaysOn>1</alwaysOn>
          <updateRate>0.0</updateRate>
          <cameraName>camera</cameraName>
          <imageTopicName>rgb/image_raw</imageTopicName>
          <cameraInfoTopicName>rgb/camera_info</cameraInfoTopicName>
          <frameName>camera_link_optical</frameName>
          <hackBaseline>0.07</hackBaseline>
          <distortionK1>0.0</distortionK1>
          <distortionK2>0.0</distortionK2>
          <distortionK3>0.0</distortionK3>
          <distortionT1>0.0</distortionT1>
          <distortionT2>0.0</distortionT2>
        </plugin> -->
      <!-- <pose frame="">0.5 0 0.3 0 -0 0</pose>
      </sensor> -->

      <sensor name="imu_sensor" type="imu">
        <pose>0.05 0 0.06 3.141593 0 0</pose>
        <always_on>1</always_on>
        <update_rate>1000</update_rate>
        <visualize>1</visualize>
        <topic>sensors/imu</topic>
        <imu>
          <topic>sensors/imu</topic>
          <angular_velocity/>
          <linear_acceleration/>
        </imu>
        <!-- <plugin name="imu_plugin" filename="libgazebo_ros_imu_sensor.so">
                <gaussianNoise>0.0</gaussianNoise>
                <always_on>1</always_on>
                <updateRateHZ>50</updateRateHZ>
                <topicName>sensors/imu</topicName>
                <bodyName>imu_link</bodyName>
                <frameName>imu_link</frameName>
                <xyzOffset>0 0 0</xyzOffset>
                <rpyOffset>0 0 0</rpyOffset>
            </plugin> -->
        <!-- <pose frame="">0 0 0.01 0 -0 0</pose> -->
      </sensor>

      <!-- <sensor name="anemometer_sensor" type="anemometer">
        <pose>0 0 0 0 0 0</pose>
        <always_on>true</always_on>
        <update_rate>50</update_rate>
        <topic>anemometer</topic>
        </sensor>
        <visual name="anemometer_visual">
        <pose>0 0 0 0 0 0</pose>
        <geometry>
        <cylinder>
        <radius>0.025</radius>
        <length>0.025</length>
        </cylinder>
        </geometry>
        <material>
          <ambient>1.0 0.0 0.0 1.0</ambient>
          <diffuse>1.0 0.0 0.0 1.0</diffuse>
          <specular>0.1 0.1 0.1 1.0</specular>
        </material>
        </visual> -->

      <!-- Approximate LY base inertial with a solid cuboid:

            m  = 3.544 kg
            Lx = 0.25 m
            Ly = 0.16 m
            Lz = 0.06 m

            as most of the mass is located at the 
            intersection of the two beams.
          -->
      <inertial>
        <pose>0.15 0 0.04 0 0 0</pose>
        <mass>3.544</mass>
        <inertia>
          <ixx>0.008623733</ixx>
          <ixy>0</ixy>
          <iyy>0.019521533</iyy>
          <iyz>0</iyz>
          <izz>0.026018867</izz>
        </inertia>
      </inertial>
    </link>

    <!-- Right wheel -->
    <link name="right_wheel_link">
      <pose>0 -0.512 0 1.570796327 0 0</pose>
      <visual name="right_wheel_visual">
        <geometry>
          <mesh>
            <uri>model://land_yacht/meshes/sand_wheel.stl</uri>
          </mesh>
        </geometry>
        <material>
          <ambient>0.5 0.5 0.5 1.0</ambient>
          <diffuse>0.5 0.5 0.5 1.0</diffuse>
          <specular>0.1 0.1 0.1 1.0</specular>
        </material>
      </visual>
      <collision name="right_wheel_collision">
        <geometry>
          <cylinder>
            <radius>0.0750</radius>
            <length>0.0235</length>
          </cylinder>
        </geometry>
      </collision>
      <inertial>
        <mass>0.112</mass>
        <inertia>
          <ixx>0.000162654</ixx>
          <ixy>0</ixy>
          <iyy>0.000162654</iyy>
          <iyz>0</iyz>
          <izz>0.000315</izz>
        </inertia>
      </inertial>
    </link>

    <joint type="revolute" name="right_wheel_joint">
      <pose>0 0 0 0 0 0</pose>
      <child>right_wheel_link</child>
      <parent>base_link</parent>
      <axis>
        <xyz>0 0 1</xyz>
        <dynamics>
          <damping>0.001</damping>
        </dynamics>
      </axis>
    </joint>

    <!-- Left wheel -->
    <link name="left_wheel_link">
      <pose>0 0.512 0 1.570796327 0 0</pose>
      <visual name="left_wheel_visual">
        <geometry>
          <mesh>
            <uri>model://land_yacht/meshes/sand_wheel.stl</uri>
          </mesh>
        </geometry>
        <material>
          <ambient>0.5 0.5 0.5 1.0</ambient>
          <diffuse>0.5 0.5 0.5 1.0</diffuse>
          <specular>0.1 0.1 0.1 1.0</specular>
        </material>
      </visual>
      <collision name="left_wheel_collision">
        <geometry>
          <cylinder>
            <radius>0.0750</radius>
            <length>0.0235</length>
          </cylinder>
        </geometry>
      </collision>
      <inertial>
        <mass>0.112</mass>
        <inertia>
          <ixx>0.000162654</ixx>
          <ixy>0</ixy>
          <iyy>0.000162654</iyy>
          <iyz>0</iyz>
          <izz>0.000315</izz>
        </inertia>
      </inertial>
    </link>

    <joint type="revolute" name="left_wheel_joint">
      <pose>0 0 0 0 0 0</pose>
      <child>left_wheel_link</child>
      <parent>base_link</parent>
      <axis>
        <xyz>0 0 1</xyz>
        <dynamics>
          <damping>0.001</damping>
        </dynamics>
      </axis>
    </joint>

    <!-- Steering unit -->
    <link name="steering_link">
      <pose>1.05 0 0 0 0 0</pose>

      <visual name="steering_visual">
        <pose>0 0 0 0 0 0</pose>
        <geometry>
          <mesh>
            <uri>model://land_yacht/meshes/land_yacht_forks_v4.stl</uri>
          </mesh>
        </geometry>
        <material>
          <ambient>0.5 0.5 0.5 1.0</ambient>
          <diffuse>0.5 0.5 0.5 1.0</diffuse>
          <specular>0.1 0.1 0.1 1.0</specular>
        </material>
      </visual>
      <collision name="steering_collision">
        <pose>-0.05 0 0.01 0 0 0</pose>
        <geometry>
          <box>
            <size>0.14 0.05 0.05</size>
          </box>
        </geometry>
      </collision>

      <inertial>
        <pose>-0.05 0 0.01 0 0 0</pose>
        <mass>0.073</mass>
        <inertia>
          <ixx>3.04167E-05</ixx>
          <ixy>0</ixy>
          <iyy>0.000134442</iyy>
          <iyz>0</iyz>
          <izz>0.000134442</izz>
        </inertia>
      </inertial>
    </link>

    <joint type="revolute" name="steering_joint">
      <pose>-0.114 0 0.045 0 0 0</pose>
      <child>steering_link</child>
      <parent>base_link</parent>
      <axis>
        <xyz>-1 0 0.700207538</xyz>
        <limit>
          <lower>-0.8</lower>
          <upper>0.8</upper>
        </limit>
      </axis>
    </joint>

    <!-- Front wheel -->
    <link name="front_wheel_link">
      <pose>1.05 0 0 1.570796327 0 0</pose>
      <visual name="front_wheel_visual">
        <geometry>
          <mesh>
            <uri>model://land_yacht/meshes/sand_wheel.stl</uri>
          </mesh>
        </geometry>
        <material>
          <ambient>0.5 0.5 0.5 1.0</ambient>
          <diffuse>0.5 0.5 0.5 1.0</diffuse>
          <specular>0.1 0.1 0.1 1.0</specular>
        </material>
      </visual>
      <collision name="front_wheel_collision">
        <geometry>
          <cylinder>
            <radius>0.0750</radius>
            <length>0.0235</length>
          </cylinder>
        </geometry>
      </collision>
      <inertial>
        <mass>0.112</mass>
        <inertia>
          <ixx>0.000162654</ixx>
          <ixy>0</ixy>
          <iyy>0.000162654</iyy>
          <iyz>0</iyz>
          <izz>0.000315</izz>
        </inertia>
      </inertial>
    </link>

    <joint type="revolute" name="front_wheel_joint">
      <pose>0 0 0 0 0 0</pose>
      <child>front_wheel_link</child>
      <parent>steering_link</parent>
      <axis>
        <xyz>0 0 1</xyz>
        <dynamics>
          <damping>0.001</damping>
        </dynamics>
      </axis>
    </joint>

    <!-- Main sail-->
    <!-- <link name="main_sail_link">
      <pose>0.5 0 0.04 0 -0.20943951 0</pose>
      <visual name="main_rig_visual">
        <geometry>
          <mesh>
            <uri>model://land_yacht/meshes/land_yacht_rig.stl</uri>
          </mesh>
        </geometry>
        <material>
          <ambient>0.5 0.5 0.5 1.0</ambient>
          <diffuse>0.5 0.5 0.5 1.0</diffuse>
          <specular>0.1 0.1 0.1 1.0</specular>
        </material>
      </visual>
      <visual name="main_sail_visual">
        <pose>-0.01 0 0.12 0 0.20943951 0</pose>
        <geometry>
          <mesh>
            <uri>model://land_yacht/meshes/land_yacht_flat_sail.stl</uri>
          </mesh>
        </geometry>
        <material>
          <ambient>0.5 0.5 0.5 0.9</ambient>
          <diffuse>0.5 0.5 0.5 0.9</diffuse>
          <specular>0.1 0.1 0.1 0.9</specular>
        </material>
      </visual>

      <visual name="cp_main_sail_visual">
        <pose>-0.15 0.0 0.75 0 0 0</pose>
        <geometry>
          <sphere>
            <radius>0.01</radius>
          </sphere>
        </geometry>
        <material>
          <ambient>1.0 0.0 0.0 1.0</ambient>
          <diffuse>1.0 0.0 0.0 1.0</diffuse>
          <specular>0.1 0.1 0.1 1.0</specular>
        </material>
      </visual>

      <collision name="main_sail_collision">
        <geometry>
          <mesh>
            <uri>model://land_yacht/meshes/land_yacht_rig.stl</uri>
          </mesh>
        </geometry>
      </collision>

      <inertial>
        <pose>-0.15 0.0 0.75 1.570796 1.570796 0</pose>
        <mass>0.5</mass>
        <inertia>
          <ixx>0.006667708</ixx>
          <ixy>0</ixy>
          <iyy>0.060001042</iyy>
          <iyz>0</iyz>
          <izz>0.066666667</izz>
        </inertia>
      </inertial>
    </link>

    <joint type="revolute" name="main_sail_joint">
      <child>main_sail_link</child>
      <parent>base_link</parent>
      <axis>
        <xyz>0 0 1</xyz>
        <initial_position>0</initial_position>
        <dynamics>
          <damping>0.001</damping>
        </dynamics>
        <limit>
          <lower>-1.396263402</lower>
          <upper>1.396263402</upper>
        </limit>
      </axis>
      <sensor name="force_torque_sensor" type="force_torque">
        <always_on>true</always_on>
        <update_rate>30</update_rate>
        <visualize>false</visualize>
      </sensor>
    </joint> -->

    <!-- <link name="thruster_link">
      <pose>0.565 0 0.22 0 -1.570796 0</pose>
      <visual name="motor_visual">
        <geometry>
          <mesh>
            <uri>model://land_yacht/meshes/motor_t3543-05.stl</uri>
          </mesh>
        </geometry>
        <material>
          <ambient>0.5 0.5 0.5 1.0</ambient>
          <diffuse>0.5 0.5 0.5 1.0</diffuse>
          <specular>0.1 0.1 0.1 1.0</specular>
        </material>
      </visual>
      <visual name="propeller_visual">
        <pose>0 0 0.05 3.141592654 0 0</pose>
        <geometry>
          <mesh>
            <uri>model://land_yacht/meshes/propeller_9x4.7.stl</uri>
          </mesh>
        </geometry>
        <material>
          <ambient>0.5 0.5 0.5 1.0</ambient>
          <diffuse>0.5 0.5 0.5 1.0</diffuse>
          <specular>0.1 0.1 0.1 1.0</specular>
        </material>
      </visual>

      <visual name="cp_prop_blade_1_visual">
        <pose>0.084 0 0.041 0 0 0</pose>
        <geometry>
          <sphere>
            <radius>0.01</radius>
          </sphere>
        </geometry>
        <material>
          <ambient>1.0 0.0 0.0 1.0</ambient>
          <diffuse>1.0 0.0 0.0 1.0</diffuse>
          <specular>0.1 0.1 0.1 1.0</specular>
        </material>
      </visual>
      <visual name="cp_prop_blade_2_visual">
        <pose>-0.084 0 0.041 0 0 0</pose>
        <geometry>
          <sphere>
            <radius>0.01</radius>
          </sphere>
        </geometry>
        <material>
          <ambient>1.0 0.0 0.0 1.0</ambient>
          <diffuse>1.0 0.0 0.0 1.0</diffuse>
          <specular>0.1 0.1 0.1 1.0</specular>
        </material>
      </visual>

      <collision name="thruster_collision">
        <pose>0 0 0.0205 0 0 0</pose>
        <geometry>
          <cylinder>
            <radius>0.0175</radius>
            <length>0.041</length>
          </cylinder>
        </geometry>
      </collision>

      <inertial>
        <pose>0 0 0.0205 0 0 0</pose>
        <mass>0.129</mass>
        <inertia>
          <ixx>2.79473E-05</ixx>
          <ixy>0</ixy>
          <iyy>2.79473E-05</iyy>
          <iyz>0</iyz>
          <izz>1.97531E-05</izz>
        </inertia>
      </inertial>
    </link>

    <joint type="revolute" name="thruster_joint">
      <child>thruster_link</child>
      <parent>base_link</parent>
      <axis>
        <xyz>0 0 1</xyz>
        <initial_position>0</initial_position>
        <dynamics>
          <damping>0.001</damping>
        </dynamics>
      </axis>
      <sensor name="force_torque_sensor" type="force_torque">
        <always_on>true</always_on>
        <update_rate>30</update_rate>
        <visualize>false</visualize>
      </sensor>
    </joint> -->

    <!-- Wing sail -->
    <link name="wing_sail_link">
      <pose>0.5 0 0.05 0 0 0</pose>
      <visual name="wing_sail_visual">
        <geometry>
          <mesh>
            <uri>model://land_yacht/meshes/wing_sail.stl</uri>
          </mesh>
        </geometry>
        <material>
          <ambient>1.0 0.4 0.0 1.0</ambient>
          <diffuse>1.0 0.4 0.0 1.0</diffuse>
          <specular>0.1 0.1 0.1 1.0</specular>
        </material>
      </visual>

      <visual name="wing_sail_elevator_spar_visual">
        <pose>-0.25 0 0.65 0 1.570796 0</pose>
        <geometry>
          <cylinder>
            <radius>0.007</radius>
            <length>1.000</length>
          </cylinder>
        </geometry>
        <material>
          <ambient>0.5 0.5 0.5 1.0</ambient>
          <diffuse>0.5 0.5 0.5 1.0</diffuse>
          <specular>0.1 0.1 0.1 1.0</specular>
        </material>
      </visual>

      <visual name="cp_wing_sail_visual">
        <pose>-0.05 0 0.65 0 0 0</pose>
        <geometry>
          <sphere>
            <radius>0.01</radius>
          </sphere>
        </geometry>
        <material>
          <ambient>1.0 0.0 0.0 1.0</ambient>
          <diffuse>1.0 0.0 0.0 1.0</diffuse>
          <specular>0.1 0.1 0.1 1.0</specular>
        </material>
      </visual>

      <collision name="wing_sail_collision">
        <geometry>
          <mesh>
            <uri>model://land_yacht/meshes/wing_sail.stl</uri>
          </mesh>
        </geometry>
      </collision>

      <inertial>
        <pose>-0.05 0.0 0.65 1.570796 1.570796 0</pose>
        <mass>2.0</mass>
        <inertia>
          <ixx>0.021666667</ixx>
          <ixy>0</ixy>
          <iyy>0.326733333</iyy>
          <iyz>0</iyz>
          <izz>0.348266667</izz>
        </inertia>
      </inertial>
    </link>

    <joint type="revolute" name="wing_sail_joint">
      <child>wing_sail_link</child>
      <parent>base_link</parent>
      <axis>
        <xyz>0 0 1</xyz>
        <initial_position>0</initial_position>
        <dynamics>
          <damping>0.1</damping>
        </dynamics>
      </axis>
      <sensor name="force_torque_sensor" type="force_torque">
        <always_on>true</always_on>
        <update_rate>30</update_rate>
        <visualize>true</visualize>
      </sensor>
    </joint>

    <!-- Wing sail elevator -->
    <link name="wing_sail_elevator_link">
      <pose>0 0 0.55 0 0 0</pose>
      <visual name="wing_sail_elevator_visual">
        <geometry>
          <mesh>
            <uri>model://land_yacht/meshes/wing_sail_elevator.stl</uri>
          </mesh>
        </geometry>
        <material>
          <ambient>1.0 0.4 0.0 1.0</ambient>
          <diffuse>1.0 0.4 0.0 1.0</diffuse>
          <specular>0.1 0.1 0.1 1.0</specular>
        </material>
      </visual>

      <visual name="cp_wing_sail_elevator_visual">
        <pose>-0.015 0 0.2 0 0 0</pose>
        <geometry>
          <sphere>
            <radius>0.01</radius>
          </sphere>
        </geometry>
        <material>
          <ambient>1.0 0.0 0.0 1.0</ambient>
          <diffuse>1.0 0.0 0.0 1.0</diffuse>
          <specular>0.1 0.1 0.1 1.0</specular>
        </material>
      </visual>

      <collision name="wing_sail_elevator_collision">
        <geometry>
          <mesh>
            <uri>model://land_yacht/meshes/wing_sail_elevator.stl</uri>
          </mesh>
        </geometry>
      </collision>

      <inertial>
        <pose>-0.015 0.0 0.2 1.570796 1.570796 0</pose>
        <mass>0.0632455</mass>
        <inertia>
          <ixx>6.75281E-05</ixx>
          <ixy>0</ixy>
          <iyy>0.001029888</iyy>
          <iyz>0</iyz>
          <izz>0.001096957</izz>
        </inertia>
      </inertial>
    </link>

    <joint type="revolute" name="wing_sail_elevator_joint">
      <child>wing_sail_elevator_link</child>
      <parent>wing_sail_link</parent>
      <axis>
        <xyz>0 0 1</xyz>
        <initial_position>0</initial_position>
        <dynamics>
          <damping>0.01</damping>
        </dynamics>
      </axis>
      <sensor name="force_torque_sensor" type="force_torque">
        <always_on>true</always_on>
        <update_rate>30</update_rate>
        <visualize>true</visualize>
      </sensor>
    </joint>

    <!-- Wing sail counterweight -->
    <link name="wing_sail_counterweight_link">
      <pose>0.65 0 0.70 0 0 0</pose>
      <visual name="wing_sail_counterweight_visual">
        <geometry>
          <sphere>
            <radius>0.025</radius>
          </sphere>
        </geometry>
        <material>
          <ambient>1.0 1.0 0.0 1.0</ambient>
          <diffuse>1.0 1.0 0.0 1.0</diffuse>
          <specular>0.1 0.1 0.1 1.0</specular>
        </material>
      </visual>

      <collision name="wing_sail_elevator_collision">
        <geometry>
          <sphere>
            <radius>0.025</radius>
          </sphere>
        </geometry>
      </collision>

      <inertial>
        <mass>0.1</mass>
        <inertia>
          <ixx>0.00025</ixx>
          <ixy>0</ixy>
          <iyy>0.00025</iyy>
          <iyz>0</iyz>
          <izz>0.00025</izz>
        </inertia>
      </inertial>
    </link>

    <joint type="fixed" name="wing_sail_counterweight_joint">
      <child>wing_sail_counterweight_link</child>
      <parent>wing_sail_link</parent>
    </joint>

  </model>
</sdf>
